Workbook

Sheet LEIA-ME
A1: Base de dados · Painel de SST e Conformidade
A2: Todos os nomes, unidades e números são fictícios e foram gerados para demonstração.
A4: Data de referência | B4: 46311 | C4: Célula editável. Prazos e situações (vencido, a vencer, vigente) são calculados a partir desta data. Para acompanhar o dia corrente, troque por =HOJE().
A6: Convenções
A7: Prefixo d = dimensão (cadastro); prefixo f = fato (medições). Chave principal entre tabelas: id_unidade (sigla da unidade).
A8: Percentuais estão em fração (0,9 = 90%). Colunas do tipo "Fórmula" são recalculadas pelo Excel e não devem ser digitadas.
A9: Valores em azul foram digitados; fundo amarelo indica célula de parâmetro.
A11: Tabelas
A12: Aba / tabela | B12: Conteúdo | C12: Linhas
A13: dUnidade | B13: Unidades (matriz e filiais), efetivo e horas-homem trabalhadas | C13: 4
A14: dSetor | B14: Setores usados no inventário de riscos, brigada e pesquisa | C14: 6
A15: dCalendario | B15: Meses do período de 12 meses analisado | C15: 12
A16: fAcidentesMensal | B16: Acidentes de trabalho por unidade e mês | C16: 48
A17: fRiscos | B17: Inventário de riscos do PGR (NR-1): perigos identificados por setor e categoria | C17: 144
A18: fBrigadistas | B18: Brigadistas voluntários e validade do treinamento (NR-23) | C18: 89
A19: fEquipamentos | B19: Extintores, hidrantes, EPIs e kits de emergência com validade | C19: 67
A20: fDocumentos | B20: Documentos obrigatórios de SST, POPs e fluxos de trabalho (vigência e revisão) | C20: 45
A21: fPesquisaDimensao | B21: Pesquisa de clima de segurança: nota por dimensão (0 a 10) | C21: 28
A22: fPesquisaSetor | B22: Pesquisa de clima de segurança: nota média por setor | C22: 24
A23: fPesquisaCiclo | B23: Evolução da nota geral da pesquisa nos últimos quatro ciclos | C23: 16
A24: fIndicadoresGestao | B24: Indicadores consolidados por unidade (janela de 12 meses até a data de referência) | C24: 4
... A32: dMetas | B32: Metas internas de prontidão dos indicadores e selos afetados (simulação) | C32: 12
A33: Conferencia | B33: KPIs recalculados com fórmulas a partir das tabelas e comparados com o painel
A34: Dicionario | B34: Descrição de cada coluna, tipo e relacionamento

Sheet dUnidade
A1: id_unidade | B1: nome_unidade | C1: tipo | D1: cidade | E1: uf | F1: colaboradores | G1: horas_homem_ano | H1: grau_risco
A2: BSB | B2: Matriz – Brasília/DF | C2: Matriz | D2: Brasília | E2: DF | F2: 820 | G2: =F2*1980 -> 1623600 | H2: 2
A3: SP | B3: Filial São Paulo/SP | C3: Filial | D3: São Paulo | E3: SP | F3: 1150 | G3: =F3*1980 -> 2277000 | H3: 3
A4: GYN | B4: Filial Goiânia/GO | C4: Filial | D4: Goiânia | E4: GO | F4: 410 | G4: =F4*1980 -> 811800 | H4: 3
A5: BH | B5: Filial Belo Horizonte/MG | C5: Filial | D5: Belo Horizonte | E5: MG | F5: 560 | G5: =F5*1980 -> 1108800 | H5: 3

Sheet dSetor
A1: setor
A2: Administrativo
A3: Operações
A4: Manutenção
A5: Logística
A6: Atendimento
A7: TI

Sheet dCalendario
A1: mes | B1: ano | C1: numero_mes | D1: nome_mes | E1: semestre
A2: 45962 | B2: 2025 | C2: 11 | D2: nov/25 | E2: 2º sem./2025
A3: 45992 | B3: 2025 | C3: 12 | D3: dez/25 | E3: 2º sem./2025
A4: 46023 | B4: 2026 | C4: 1 | D4: jan/26 | E4: 1º sem./2026
A5: 46054 | B5: 2026 | C5: 2 | D5: fev/26 | E5: 1º sem./2026
A6: 46082 | B6: 2026 | C6: 3 | D6: mar/26 | E6: 1º sem./2026
A7: 46113 | B7: 2026 | C7: 4 | D7: abr/26 | E7: 1º sem./2026
A8: 46143 | B8: 2026 | C8: 5 | D8: mai/26 | E8: 1º sem./2026
A9: 46174 | B9: 2026 | C9: 6 | D9: jun/26 | E9: 1º sem./2026
A10: 46204 | B10: 2026 | C10: 7 | D10: jul/26 | E10: 2º sem./2026
A11: 46235 | B11: 2026 | C11: 8 | D11: ago/26 | E11: 2º sem./2026
A12: 46266 | B12: 2026 | C12: 9 | D12: set/26 | E12: 2º sem./2026
A13: 46296 | B13: 2026 | C13: 10 | D13: out/26 | E13: 2º sem./2026

Sheet fAcidentesMensal
A1: id_unidade | B1: mes | C1: acidentes_caf | D1: acidentes_saf
A2: BSB | B2: 45962 | C2: 0 | D2: 1
A3: BSB | B3: 45992 | C3: 0 | D3: 0
A4: BSB | B4: 46023 | C4: 1 | D4: 0
A5: BSB | B5: 46054 | C5: 0 | D5: 2
A6: BSB | B6: 46082 | C6: 1 | D6: 0
A7: BSB | B7: 46113 | C7: 0 | D7: 1
A8: BSB | B8: 46143 | C8: 0 | D8: 1
A9: BSB | B9: 46174 | C9: 1 | D9: 0
A10: BSB | B10: 46204 | C10: 0 | D10: 1
A11: BSB | B11: 46235 | C11: 0 | D11: 2
A12: BSB | B12: 46266 | C12: 0 | D12: 0
A13: BSB | B13: 46296 | C13: 0 | D13: 1
... A49: BH | B49: 46296 | C49: 1 | D49: 1

Sheet fRiscos
A1: id_unidade | B1: setor | C1: categoria_risco | D1: qtd_perigos
A2: BSB | B2: Administrativo | C2: Físico | D2: 1
A3: BSB | B3: Administrativo | C3: Químico | D3: 0
A4: BSB | B4: Administrativo | C4: Biológico | D4: 0
A5: BSB | B5: Administrativo | C5: Ergonômico | D5: 5
A6: BSB | B6: Administrativo | C6: Acidentes | D6: 1
A7: BSB | B7: Administrativo | C7: Psicossociais | D7: 4
A8: BSB | B8: Operações | C8: Físico | D8: 5
A9: BSB | B9: Operações | C9: Químico | D9: 3
A10: BSB | B10: Operações | C10: Biológico | D10: 1
A11: BSB | B11: Operações | C11: Ergonômico | D11: 3
A12: BSB | B12: Operações | C12: Acidentes | D12: 4
A13: BSB | B13: Operações | C13: Psicossociais | D13: 3
... A145: BH | B145: TI | C145: Psicossociais | D145: 3

Sheet fBrigadistas
A1: id_brigadista | B1: nome | C1: id_unidade | D1: setor | E1: turno | F1: data_ultimo_treinamento | G1: data_validade | H1: dias_para_vencimento | I1: situacao
A2: BSB-B001 | B2: Vanessa Nunes Souza | C2: BSB | D2: Administrativo | E2: Manhã | F2: 46119 | G2: 46484 | H2: =G2-'LEIA-ME'!$B$4 -> 173 | I2: =IF(H2<0,"Vencido",IF(H2<=30,"Vence em até 30 dias",IF(H2<=60,"Vence em até 60 dias","Válido"))) -> Válido
A3: BSB-B002 | B3: Gabriela Gomes Costa | C3: BSB | D3: Administrativo | E3: Noite | F3: 46275 | G3: 46640 | H3: =G3-'LEIA-ME'!$B$4 -> 329 | I3: =IF(H3<0,"Vencido",IF(H3<=30,"Vence em até 30 dias",IF(H3<=60,"Vence em até 60 dias","Válido"))) -> Válido
A4: BSB-B003 | B4: Yasmin Oliveira Souza | C4: BSB | D4: Operações | E4: Administrativo | F4: 46170 | G4: 46535 | H4: =G4-'LEIA-ME'!$B$4 -> 224 | I4: =IF(H4<0,"Vencido",IF(H4<=30,"Vence em até 30 dias",IF(H4<=60,"Vence em até 60 dias","Válido"))) -> Válido
A5: BSB-B004 | B5: Otávio Rocha Cardoso | C5: BSB | D5: Operações | E5: Administrativo | F5: 45984 | G5: 46349 | H5: =G5-'LEIA-ME'!$B$4 -> 38 | I5: =IF(H5<0,"Vencido",IF(H5<=30,"Vence em até 30 dias",IF(H5<=60,"Vence em até 60 dias","Válido"))) -> Vence em até 60 dias
A6: BSB-B005 | B6: Leandro Silva Teixeira | C6: BSB | D6: Manutenção | E6: Manhã | F6: 46271 | G6: 46636 | H6: =G6-'LEIA-ME'!$B$4 -> 325 | I6: =IF(H6<0,"Vencido",IF(H6<=30,"Vence em até 30 dias",IF(H6<=60,"Vence em até 60 dias","Válido"))) -> Válido
A7: BSB-B006 | B7: Bruno Freitas Martins | C7: BSB | D7: TI | E7: Manhã | F7: 46186 | G7: 46551 | H7: =G7-'LEIA-ME'!$B$4 -> 240 | I7: =IF(H7<0,"Vencido",IF(H7<=30,"Vence em até 30 dias",IF(H7<=60,"Vence em até 60 dias","Válido"))) -> Válido
A8: BSB-B007 | B8: Tatiane Barbosa Moreira | C8: BSB | D8: Atendimento | E8: Noite | F8: 46044 | G8: 46409 | H8: =G8-'LEIA-ME'!$B$4 -> 98 | I8: =IF(H8<0,"Vencido",IF(H8<=30,"Vence em até 30 dias",IF(H8<=60,"Vence em até 60 dias","Válido"))) -> Válido
A9: BSB-B008 | B9: Juliana Moreira Teixeira | C9: BSB | D9: Manutenção | E9: Manhã | F9: 45950 | G9: 46315 | H9: =G9-'LEIA-ME'!$B$4 -> 4 | I9: =IF(H9<0,"Vencido",IF(H9<=30,"Vence em até 30 dias",IF(H9<=60,"Vence em até 60 dias","Válido"))) -> Vence em até 30 dias
A10: BSB-B009 | B10: Isabela Dias Costa | C10: BSB | D10: Operações | E10: Noite | F10: 46108 | G10: 46473 | H10: =G10-'LEIA-ME'!$B$4 -> 162 | I10: =IF(H10<0,"Vencido",IF(H10<=30,"Vence em até 30 dias",IF(H10<=60,"Vence em até 60 dias","Válido"))) -> Válido
A11: BSB-B010 | B11: Priscila Oliveira Carvalho | C11: BSB | D11: TI | E11: Noite | F11: 46180 | G11: 46545 | H11: =G11-'LEIA-ME'!$B$4 -> 234 | I11: =IF(H11<0,"Vencido",IF(H11<=30,"Vence em até 30 dias",IF(H11<=60,"Vence em até 60 dias","Válido"))) -> Válido
A12: BSB-B011 | B12: Isabela Gomes Vieira | C12: BSB | D12: Atendimento | E12: Administrativo | F12: 46076 | G12: 46441 | H12: =G12-'LEIA-ME'!$B$4 -> 130 | I12: =IF(H12<0,"Vencido",IF(H12<=30,"Vence em até 30 dias",IF(H12<=60,"Vence em até 60 dias","Válido"))) -> Válido
A13: BSB-B012 | B13: Diego Carvalho Lopes | C13: BSB | D13: Atendimento | E13: Tarde | F13: 46223 | G13: 46588 | H13: =G13-'LEIA-ME'!$B$4 -> 277 | I13: =IF(H13<0,"Vencido",IF(H13<=30,"Vence em até 30 dias",IF(H13<=60,"Vence em até 60 dias","Válido"))) -> Válido
... A90: BH-B017 | B90: Otávio Silva Vieira | C90: BH | D90: Manutenção | E90: Tarde | F90: 45919 | G90: 46284 | H90: =G90-'LEIA-ME'!$B$4 -> -27 | I90: =IF(H90<0,"Vencido",IF(H90<=30,"Vence em até 30 dias",IF(H90<=60,"Vence em até 60 dias","Válido"))) -> Vencido

Sheet fEquipamentos
A1: codigo | B1: item | C1: categoria | D1: local | E1: id_unidade | F1: quantidade | G1: data_validade | H1: dias_para_vencimento | I1: situacao
A2: BSB-EXT-001 | B2: Extintor PQS ABC 6 kg | C2: Extintor | D2: Almoxarifado | E2: BSB | F2: 1 | G2: 46528 | H2: =G2-'LEIA-ME'!$B$4 -> 217 | I2: =IF(H2<0,"Vencido",IF(H2<=30,"Até 30 dias",IF(H2<=90,"31 a 90 dias","Em dia"))) -> Em dia
A3: BSB-EXT-002 | B3: Extintor PQS ABC 6 kg | C3: Extintor | D3: Sala de servidores | E3: BSB | F3: 1 | G3: 46575 | H3: =G3-'LEIA-ME'!$B$4 -> 264 | I3: =IF(H3<0,"Vencido",IF(H3<=30,"Até 30 dias",IF(H3<=90,"31 a 90 dias","Em dia"))) -> Em dia
A4: BSB-EXT-003 | B4: Extintor CO₂ 6 kg | C4: Extintor | D4: Bloco A – térreo | E4: BSB | F4: 1 | G4: 46654 | H4: =G4-'LEIA-ME'!$B$4 -> 343 | I4: =IF(H4<0,"Vencido",IF(H4<=30,"Até 30 dias",IF(H4<=90,"31 a 90 dias","Em dia"))) -> Em dia
A5: BSB-EXT-004 | B5: Extintor água pressurizada 10 L | C5: Extintor | D5: Oficina de manutenção | E5: BSB | F5: 1 | G5: 46495 | H5: =G5-'LEIA-ME'!$B$4 -> 184 | I5: =IF(H5<0,"Vencido",IF(H5<=30,"Até 30 dias",IF(H5<=90,"31 a 90 dias","Em dia"))) -> Em dia
A6: BSB-EXT-005 | B6: Extintor água pressurizada 10 L | C6: Extintor | D6: Recepção | E6: BSB | F6: 1 | G6: 46294 | H6: =G6-'LEIA-ME'!$B$4 -> -17 | I6: =IF(H6<0,"Vencido",IF(H6<=30,"Até 30 dias",IF(H6<=90,"31 a 90 dias","Em dia"))) -> Vencido
A7: BSB-EXT-006 | B7: Extintor água pressurizada 10 L | C7: Extintor | D7: Bloco A – térreo | E7: BSB | F7: 1 | G7: 46453 | H7: =G7-'LEIA-ME'!$B$4 -> 142 | I7: =IF(H7<0,"Vencido",IF(H7<=30,"Até 30 dias",IF(H7<=90,"31 a 90 dias","Em dia"))) -> Em dia
A8: BSB-HID-001 | B8: Mangueira de hidrante 15 m | C8: Hidrante | D8: Recepção | E8: BSB | F8: 1 | G8: 46507 | H8: =G8-'LEIA-ME'!$B$4 -> 196 | I8: =IF(H8<0,"Vencido",IF(H8<=30,"Até 30 dias",IF(H8<=90,"31 a 90 dias","Em dia"))) -> Em dia
A9: BSB-EPI-001 | B9: Máscara PFF2 (lote) | C9: EPI | D9: Almoxarifado | E9: BSB | F9: 250 | G9: 46630 | H9: =G9-'LEIA-ME'!$B$4 -> 319 | I9: =IF(H9<0,"Vencido",IF(H9<=30,"Até 30 dias",IF(H9<=90,"31 a 90 dias","Em dia"))) -> Em dia
A10: BSB-EPI-002 | B10: Luva nitrílica (lote) | C10: EPI | D10: Bloco B – operação | E10: BSB | F10: 270 | G10: 46427 | H10: =G10-'LEIA-ME'!$B$4 -> 116 | I10: =IF(H10<0,"Vencido",IF(H10<=30,"Até 30 dias",IF(H10<=90,"31 a 90 dias","Em dia"))) -> Em dia
A11: BSB-EPI-003 | B11: Protetor auricular tipo plug (lote) | C11: EPI | D11: Bloco A – 1º andar | E11: BSB | F11: 380 | G11: 46805 | H11: =G11-'LEIA-ME'!$B$4 -> 494 | I11: =IF(H11<0,"Vencido",IF(H11<=30,"Até 30 dias",IF(H11<=90,"31 a 90 dias","Em dia"))) -> Em dia
A12: BSB-EPI-004 | B12: Capacete de segurança classe B | C12: EPI | D12: Bloco A – 1º andar | E12: BSB | F12: 80 | G12: 46378 | H12: =G12-'LEIA-ME'!$B$4 -> 67 | I12: =IF(H12<0,"Vencido",IF(H12<=30,"Até 30 dias",IF(H12<=90,"31 a 90 dias","Em dia"))) -> 31 a 90 dias
A13: BSB-EPI-005 | B13: Óculos de proteção incolor (lote) | C13: EPI | D13: Bloco A – 1º andar | E13: BSB | F13: 280 | G13: 46338 | H13: =G13-'LEIA-ME'!$B$4 -> 27 | I13: =IF(H13<0,"Vencido",IF(H13<=30,"Até 30 dias",IF(H13<=90,"31 a 90 dias","Em dia"))) -> Até 30 dias
... A68: BH-EMG-002 | B68: Luminária de emergência (bateria) | C68: Emergência | D68: Almoxarifado | E68: BH | F68: 1 | G68: 46383 | H68: =G68-'LEIA-ME'!$B$4 -> 72 | I68: =IF(H68<0,"Vencido",IF(H68<=30,"Até 30 dias",IF(H68<=90,"31 a 90 dias","Em dia"))) -> 31 a 90 dias

Sheet fDocumentos
A1: codigo | B1: documento | C1: tipo | D1: norma | E1: id_unidade | F1: responsavel | G1: periodicidade | H1: data_ultima_revisao | I1: data_proxima_revisao | J1: dias_para_revisao | K1: vigencia | L1: status_fluxo | M1: progresso_fluxo
A2: PGR | B2: Programa de Gerenciamento de Riscos | C2: Programa | D2: NR-1 | E2: BSB | F2: Eng. de Segurança | G2: Bienal ou por mudança no processo | H2: 45698 | I2: 46428 | J2: =I2-'LEIA-ME'!$B$4 -> 117 | K2: =IF(J2<0,"Vencido",IF(J2<=30,"Até 30 dias",IF(J2<=60,"Até 60 dias","Vigente"))) -> Vigente | L2: Atualizado | M2: 1
A3: PCMSO | B3: Programa de Controle Médico de Saúde Ocupacional | C3: Programa | D3: NR-7 | E3: BSB | F3: Médico do Trabalho | G3: Anual (relatório analítico) | H3: 46118 | I3: 46483 | J3: =I3-'LEIA-ME'!$B$4 -> 172 | K3: =IF(J3<0,"Vencido",IF(J3<=30,"Até 30 dias",IF(J3<=60,"Até 60 dias","Vigente"))) -> Vigente | L3: Atualizado | M3: 1
A4: LTCAT | B4: Laudo Técnico das Condições Ambientais do Trabalho | C4: Laudo | D4: Lei 8.213/91 · NR-15 | E4: BSB | F4: Eng. de Segurança | G4: Anual ou por mudança no ambiente | H4: 46197 | I4: 46562 | J4: =I4-'LEIA-ME'!$B$4 -> 251 | K4: =IF(J4<0,"Vencido",IF(J4<=30,"Até 30 dias",IF(J4<=60,"Até 60 dias","Vigente"))) -> Vigente | L4: Atualizado | M4: 1
A5: AET | B5: Análise Ergonômica do Trabalho | C5: Laudo | D5: NR-17 | E5: BSB | F5: Ergonomista | G5: Bienal | H5: 45594 | I5: 46324 | J5: =I5-'LEIA-ME'!$B$4 -> 13 | K5: =IF(J5<0,"Vencido",IF(J5<=30,"Até 30 dias",IF(J5<=60,"Até 60 dias","Vigente"))) -> Até 30 dias | L5: Atualizado | M5: 1
A6: PAE | B6: Plano de Atendimento a Emergências | C6: Plano | D6: NR-23 | E6: BSB | F6: Coord. da Brigada | G6: Anual | H6: 46013 | I6: 46378 | J6: =I6-'LEIA-ME'!$B$4 -> 67 | K6: =IF(J6<0,"Vencido",IF(J6<=30,"Até 30 dias",IF(J6<=60,"Até 60 dias","Vigente"))) -> Vigente | L6: Atualizado | M6: 1
A7: POP-SST-01 | B7: Investigação e análise de acidentes | C7: POP | D7: NR-1 | E7: BSB | F7: Téc. de Segurança | G7: Anual | H7: 46012 | I7: 46377 | J7: =I7-'LEIA-ME'!$B$4 -> 66 | K7: =IF(J7<0,"Vencido",IF(J7<=30,"Até 30 dias",IF(J7<=60,"Até 60 dias","Vigente"))) -> Vigente | L7: Atualizado | M7: 1
A8: POP-SST-02 | B8: Entrega, guarda e substituição de EPI | C8: POP | D8: NR-6 | E8: BSB | F8: Téc. de Segurança | G8: Anual | H8: 45998 | I8: 46363 | J8: =I8-'LEIA-ME'!$B$4 -> 52 | K8: =IF(J8<0,"Vencido",IF(J8<=30,"Até 30 dias",IF(J8<=60,"Até 60 dias","Vigente"))) -> Até 60 dias | L8: Atualizado | M8: 1
A9: POP-SST-03 | B9: Inspeção mensal de extintores e hidrantes | C9: POP | D9: NR-23 | E9: BSB | F9: Coord. da Brigada | G9: Anual | H9: 46229 | I9: 46594 | J9: =I9-'LEIA-ME'!$B$4 -> 283 | K9: =IF(J9<0,"Vencido",IF(J9<=30,"Até 30 dias",IF(J9<=60,"Até 60 dias","Vigente"))) -> Vigente | L9: Atualizado | M9: 1
A10: POP-SST-04 | B10: Emissão de CAT e envio ao eSocial (S-2210) | C10: POP | D10: eSocial | E10: BSB | F10: Gestão de Pessoas | G10: Anual | H10: 45957 | I10: 46322 | J10: =I10-'LEIA-ME'!$B$4 -> 11 | K10: =IF(J10<0,"Vencido",IF(J10<=30,"Até 30 dias",IF(J10<=60,"Até 60 dias","Vigente"))) -> Até 30 dias | L10: Atualizado | M10: 1
A11: FLX-SST-01 | B11: Fluxo de exames ocupacionais (ASO) | C11: Fluxo | D11: NR-7 | E11: BSB | F11: Medicina do Trabalho | G11: Anual | H11: 45991 | I11: 46356 | J11: =I11-'LEIA-ME'!$B$4 -> 45 | K11: =IF(J11<0,"Vencido",IF(J11<=30,"Até 30 dias",IF(J11<=60,"Até 60 dias","Vigente"))) -> Até 60 dias | L11: Em revisão | M11: 0.57
A12: FLX-SST-02 | B12: Fluxo de permissão para trabalho de risco | C12: Fluxo | D12: NR-10 / NR-35 | E12: BSB | F12: Eng. de Segurança | G12: Anual | H12: 46162 | I12: 46527 | J12: =I12-'LEIA-ME'!$B$4 -> 216 | K12: =IF(J12<0,"Vencido",IF(J12<=30,"Até 30 dias",IF(J12<=60,"Até 60 dias","Vigente"))) -> Vigente | L12: Em revisão | M12: 0.44
A13: PGR | B13: Programa de Gerenciamento de Riscos | C13: Programa | D13: NR-1 | E13: SP | F13: Eng. de Segurança | G13: Bienal ou por mudança no processo | H13: 45589 | I13: 46319 | J13: =I13-'LEIA-ME'!$B$4 -> 8 | K13: =IF(J13<0,"Vencido",IF(J13<=30,"Até 30 dias",IF(J13<=60,"Até 60 dias","Vigente"))) -> Até 30 dias | L13: Atualizado | M13: 1
... A46: FLX-SST-02 | B46: Fluxo de permissão para trabalho de risco | C46: Fluxo | D46: NR-10 / NR-35 | E46: BH | F46: Eng. de Segurança | G46: Anual | H46: 46237 | I46: 46602 | J46: =I46-'LEIA-ME'!$B$4 -> 291 | K46: =IF(J46<0,"Vencido",IF(J46<=30,"Até 30 dias",IF(J46<=60,"Até 60 dias","Vigente"))) -> Vigente | L46: Em revisão | M46: 0.79

Sheet fPesquisaDimensao
A1: id_unidade | B1: dimensao | C1: nota_ciclo_anterior | D1: nota_ciclo_atual | E1: variacao
A2: BSB | B2: Percepção de risco | C2: 8.45 | D2: 8.33 | E2: =D2-C2 -> -0.12
A3: BSB | B3: Eficácia dos treinamentos | C3: 7.89 | D3: 8.25 | E3: =D3-C3 -> 0.36
A4: BSB | B4: Segurança psicológica | C4: 7.05 | D4: 6.89 | E4: =D4-C4 -> -0.16
A5: BSB | B5: Liderança engajada em SST | C5: 7.52 | D5: 7.31 | E5: =D5-C5 -> -0.21
A6: BSB | B6: Comunicação de riscos | C6: 7.41 | D6: 8 | E6: =D6-C6 -> 0.59
A7: BSB | B7: Adequação dos EPIs | C7: 7.63 | D7: 8.34 | E7: =D7-C7 -> 0.71
A8: BSB | B8: Confiança no canal de reporte | C8: 6.69 | D8: 7.13 | E8: =D8-C8 -> 0.44
A9: SP | B9: Percepção de risco | C9: 7.12 | D9: 7.61 | E9: =D9-C9 -> 0.49
A10: SP | B10: Eficácia dos treinamentos | C10: 6.44 | D10: 6.93 | E10: =D10-C10 -> 0.49
A11: SP | B11: Segurança psicológica | C11: 6.04 | D11: 6.61 | E11: =D11-C11 -> 0.57
A12: SP | B12: Liderança engajada em SST | C12: 6.51 | D12: 7 | E12: =D12-C12 -> 0.49
A13: SP | B13: Comunicação de riscos | C13: 7.36 | D13: 7.28 | E13: =D13-C13 -> -0.08
... A29: BH | B29: Confiança no canal de reporte | C29: 5.34 | D29: 5.81 | E29: =D29-C29 -> 0.47

Sheet fPesquisaSetor
A1: id_unidade | B1: setor | C1: nota_media
A2: BSB | B2: Administrativo | C2: 8.05
A3: BSB | B3: Operações | C3: 7.61
A4: BSB | B4: Manutenção | C4: 7.83
A5: BSB | B5: Logística | C5: 7.17
A6: BSB | B6: Atendimento | C6: 7.59
A7: BSB | B7: TI | C7: 8.36
A8: SP | B8: Administrativo | C8: 7.85
A9: SP | B9: Operações | C9: 6.87
A10: SP | B10: Manutenção | C10: 7.35
A11: SP | B11: Logística | C11: 6.83
A12: SP | B12: Atendimento | C12: 7.29
A13: SP | B13: TI | C13: 8.02
... A25: BH | B25: TI | C25: 6.78

Sheet fPesquisaCiclo
A1: id_unidade | B1: ordem_ciclo | C1: ciclo | D1: nota_geral
A2: BSB | B2: 1 | C2: 1º sem./2025 | D2: 6.91
A3: BSB | B3: 2 | C3: 2º sem./2025 | D3: 7.22
A4: BSB | B4: 3 | C4: 1º sem./2026 | D4: 7.52
A5: BSB | B5: 4 | C5: 2º sem./2026 | D5: 7.75
A6: SP | B6: 1 | C6: 1º sem./2025 | D6: 6.25
A7: SP | B7: 2 | C7: 2º sem./2025 | D7: 6.73
A8: SP | B8: 3 | C8: 1º sem./2026 | D8: 6.75
A9: SP | B9: 4 | C9: 2º sem./2026 | D9: 7.03
A10: GYN | B10: 1 | C10: 1º sem./2025 | D10: 5.68
A11: GYN | B11: 2 | C11: 2º sem./2025 | D11: 6.24
A12: GYN | B12: 3 | C12: 1º sem./2026 | D12: 6.72
A13: GYN | B13: 4 | C13: 2º sem./2026 | D13: 6.76
... A17: BH | B17: 4 | C17: 2º sem./2026 | D17: 6.33

Sheet fIndicadoresGestao
A1: id_unidade | B1: data_referencia | C1: dias_perdidos_12m | D1: dias_sem_acidente_caf | E1: conformidade_nr1 | F1: trust_index | G1: horas_treinamento_sst_colab | H1: ncs_abertas_auditoria | I1: investigacoes_no_prazo | J1: absenteismo | K1: turnover_voluntario | L1: brigadistas_exigidos | M1: respondentes_pesquisa | N1: periodicos_total | O1: periodicos_vencidos | P1: periodicos_a_vencer_30d | Q1: desligamentos_12m | R1: ppp_emitidos
A2: BSB | B2: 46311 | C2: 41 | D2: 128 | E2: 0.9058 | F2: 0.744 | G2: 13.8 | H2: 2 | I2: 0.9153 | J2: 0.0245 | K2: 0.0918 | L2: 23 | M2: 718 | N2: 820 | O2: 37 | P2: 20 | Q2: 75 | R2: 72
A3: SP | B3: 46311 | C3: 97 | D3: 47 | E3: 0.8717 | F3: 0.7405 | G3: 12.7 | H3: 5 | I3: 0.8767 | J3: 0.0283 | K3: 0.1096 | L3: 32 | M3: 931 | N3: 1150 | O3: 77 | P3: 41 | Q3: 126 | R3: 118
A4: GYN | B4: 46311 | C4: 73 | D4: 22 | E4: 0.8541 | F4: 0.662 | G4: 12 | H4: 4 | I4: 0.8676 | J4: 0.0321 | K4: 0.1301 | L4: 11 | M4: 314 | N4: 410 | O4: 39 | P4: 13 | Q4: 53 | R4: 50
A5: BH | B5: 46311 | C5: 138 | D5: 9 | E5: 0.8167 | F5: 0.6812 | G5: 10.5 | H5: 7 | I5: 0.796 | J5: 0.0325 | K5: 0.1242 | L5: 16 | M5: 409 | N5: 560 | O5: 57 | P5: 15 | Q5: 70 | R5: 63

Sheet fSesmt
A1: id_unidade | B1: funcao | C1: exigido | D1: existente | E1: deficit
A2: BSB | B2: Técnico de Segurança do Trabalho | C2: 2 | D2: 2 | E2: =MAX(0,C2-D2) -> 0
A3: BSB | B3: Engenheiro de Segurança do Trabalho | C3: 1 | D3: 1 | E3: =MAX(0,C3-D3) -> 0
A4: BSB | B4: Aux./Téc. de Enfermagem do Trabalho | C4: 1 | D4: 1 | E4: =MAX(0,C4-D4) -> 0
A5: BSB | B5: Enfermeiro do Trabalho | C5: 0 | D5: 0 | E5: =MAX(0,C5-D5) -> 0
A6: BSB | B6: Médico do Trabalho | C6: 1 | D6: 1 | E6: =MAX(0,C6-D6) -> 0
A7: SP | B7: Técnico de Segurança do Trabalho | C7: 4 | D7: 4 | E7: =MAX(0,C7-D7) -> 0
A8: SP | B8: Engenheiro de Segurança do Trabalho | C8: 1 | D8: 1 | E8: =MAX(0,C8-D8) -> 0
A9: SP | B9: Aux./Téc. de Enfermagem do Trabalho | C9: 1 | D9: 1 | E9: =MAX(0,C9-D9) -> 0
A10: SP | B10: Enfermeiro do Trabalho | C10: 1 | D10: 1 | E10: =MAX(0,C10-D10) -> 0
A11: SP | B11: Médico do Trabalho | C11: 1 | D11: 1 | E11: =MAX(0,C11-D11) -> 0
A12: GYN | B12: Técnico de Segurança do Trabalho | C12: 2 | D12: 2 | E12: =MAX(0,C12-D12) -> 0
A13: GYN | B13: Engenheiro de Segurança do Trabalho | C13: 1 | D13: 0 | E13: =MAX(0,C13-D13) -> 1
... A21: BH | B21: Médico do Trabalho | C21: 1 | D21: 1 | E21: =MAX(0,C21-D21) -> 0

Sheet fAsos
A1: id_unidade | B1: tipo_aso | C1: no_prazo | D1: fora_do_prazo | E1: total
A2: BSB | B2: Admissional | C2: 82 | D2: 1 | E2: =C2+D2 -> 83
A3: BSB | B3: Periódico | C3: 753 | D3: 26 | E3: =C3+D3 -> 779
A4: BSB | B4: Retorno ao trabalho | C4: 24 | D4: 1 | E4: =C4+D4 -> 25
A5: BSB | B5: Mudança de risco | C5: 16 | D5: 0 | E5: =C5+D5 -> 16
A6: BSB | B6: Demissional | C6: 74 | D6: 1 | E6: =C6+D6 -> 75
A7: SP | B7: Admissional | C7: 134 | D7: 5 | E7: =C7+D7 -> 139
A8: SP | B8: Periódico | C8: 1043 | D8: 50 | E8: =C8+D8 -> 1093
A9: SP | B9: Retorno ao trabalho | C9: 34 | D9: 1 | E9: =C9+D9 -> 35
A10: SP | B10: Mudança de risco | C10: 22 | D10: 1 | E10: =C10+D10 -> 23
A11: SP | B11: Demissional | C11: 122 | D11: 4 | E11: =C11+D11 -> 126
A12: GYN | B12: Admissional | C12: 57 | D12: 2 | E12: =C12+D12 -> 59
A13: GYN | B13: Periódico | C13: 350 | D13: 40 | E13: =C13+D13 -> 390
... A21: BH | B21: Demissional | C21: 66 | D21: 4 | E21: =C21+D21 -> 70

Sheet fPeriodicosPendentes
A1: nome | B1: id_unidade | C1: setor | D1: funcao | E1: data_ultimo_periodico | F1: data_vencimento | G1: dias_para_vencimento | H1: situacao
A2: Caio Carvalho Pereira | B2: BSB | C2: TI | D2: Eletricista | E2: 45933 | F2: 46298 | G2: =F2-'LEIA-ME'!$B$4 -> -13 | H2: =IF(G2<0,"Vencido","Vence em até 30 dias") -> Vencido
A3: Lucas Moreira Lopes | B3: BSB | C3: Atendimento | D3: Técnico de manutenção | E3: 45811 | F3: 46176 | G3: =F3-'LEIA-ME'!$B$4 -> -135 | H3: =IF(G3<0,"Vencido","Vence em até 30 dias") -> Vencido
A4: Yasmin Ferreira Souza | B4: BSB | C4: TI | D4: Técnico de manutenção | E4: 45796 | F4: 46161 | G4: =F4-'LEIA-ME'!$B$4 -> -150 | H4: =IF(G4<0,"Vencido","Vence em até 30 dias") -> Vencido
A5: Mariana Rodrigues Silva | B5: BSB | C5: Atendimento | D5: Conferente | E5: 45799 | F5: 46164 | G5: =F5-'LEIA-ME'!$B$4 -> -147 | H5: =IF(G5<0,"Vencido","Vence em até 30 dias") -> Vencido
A6: Wesley Dias Cardoso | B6: BSB | C6: Administrativo | D6: Analista de TI | E6: 45888 | F6: 46253 | G6: =F6-'LEIA-ME'!$B$4 -> -58 | H6: =IF(G6<0,"Vencido","Vence em até 30 dias") -> Vencido
A7: Rodrigo Teixeira Pereira | B7: BSB | C7: Operações | D7: Técnico de manutenção | E7: 45796 | F7: 46161 | G7: =F7-'LEIA-ME'!$B$4 -> -150 | H7: =IF(G7<0,"Vencido","Vence em até 30 dias") -> Vencido
A8: Priscila Costa Dias | B8: BSB | C8: Logística | D8: Técnico de manutenção | E8: 45879 | F8: 46244 | G8: =F8-'LEIA-ME'!$B$4 -> -67 | H8: =IF(G8<0,"Vencido","Vence em até 30 dias") -> Vencido
A9: Eduarda Costa Moreira | B9: BSB | C9: TI | D9: Assistente administrativo | E9: 45894 | F9: 46259 | G9: =F9-'LEIA-ME'!$B$4 -> -52 | H9: =IF(G9<0,"Vencido","Vence em até 30 dias") -> Vencido
A10: Eduarda Cardoso Costa | B10: BSB | C10: TI | D10: Eletricista | E10: 45957 | F10: 46322 | G10: =F10-'LEIA-ME'!$B$4 -> 11 | H10: =IF(G10<0,"Vencido","Vence em até 30 dias") -> Vence em até 30 dias
A11: Otávio Vieira Barbosa | B11: BSB | C11: Operações | D11: Atendente | E11: 45947 | F11: 46312 | G11: =F11-'LEIA-ME'!$B$4 -> 1 | H11: =IF(G11<0,"Vencido","Vence em até 30 dias") -> Vence em até 30 dias
A12: Vanessa Pereira Rocha | B12: BSB | C12: TI | D12: Analista de TI | E12: 45954 | F12: 46319 | G12: =F12-'LEIA-ME'!$B$4 -> 8 | H12: =IF(G12<0,"Vencido","Vence em até 30 dias") -> Vence em até 30 dias
A13: Rodrigo Barbosa Gomes | B13: BSB | C13: Administrativo | D13: Auxiliar de logística | E13: 45975 | F13: 46340 | G13: =F13-'LEIA-ME'!$B$4 -> 29 | H13: =IF(G13<0,"Vencido","Vence em até 30 dias") -> Vence em até 30 dias
... A49: Karina Lopes Rodrigues | B49: BH | C49: Atendimento | D49: Eletricista | E49: 45956 | F49: 46321 | G49: =F49-'LEIA-ME'!$B$4 -> 10 | H49: =IF(G49<0,"Vencido","Vence em até 30 dias") -> Vence em até 30 dias

Sheet fExames
A1: id_unidade | B1: exame | C1: programados | D1: realizados | E1: pct_realizado
A2: BSB | B2: Audiometria | C2: 180 | D2: 165 | E2: =IF(C2=0,0,D2/C2) -> 0.91666667
A3: BSB | B3: Hemograma completo | C3: 492 | D3: 492 | E3: =IF(C3=0,0,D3/C3) -> 1
A4: BSB | B4: Glicemia de jejum | C4: 328 | D4: 324 | E4: =IF(C4=0,0,D4/C4) -> 0.98780488
A5: BSB | B5: Acuidade visual | C5: 246 | D5: 239 | E5: =IF(C5=0,0,D5/C5) -> 0.97154472
A6: BSB | B6: Espirometria | C6: 164 | D6: 137 | E6: =IF(C6=0,0,D6/C6) -> 0.83536585
A7: BSB | B7: Raio-X de tórax (padrão OIT) | C7: 82 | D7: 65 | E7: =IF(C7=0,0,D7/C7) -> 0.79268293
A8: SP | B8: Audiometria | C8: 633 | D8: 543 | E8: =IF(C8=0,0,D8/C8) -> 0.85781991
A9: SP | B9: Hemograma completo | C9: 690 | D9: 690 | E9: =IF(C9=0,0,D9/C9) -> 1
A10: SP | B10: Glicemia de jejum | C10: 460 | D10: 459 | E10: =IF(C10=0,0,D10/C10) -> 0.99782609
A11: SP | B11: Acuidade visual | C11: 345 | D11: 319 | E11: =IF(C11=0,0,D11/C11) -> 0.92463768
A12: SP | B12: Espirometria | C12: 230 | D12: 195 | E12: =IF(C12=0,0,D12/C12) -> 0.84782609
A13: SP | B13: Raio-X de tórax (padrão OIT) | C13: 115 | D13: 90 | E13: =IF(C13=0,0,D13/C13) -> 0.7826087
... A25: BH | B25: Raio-X de tórax (padrão OIT) | C25: 56 | D25: 44 | E25: =IF(C25=0,0,D25/C25) -> 0.78571429

Sheet fAfastamentos
A1: id_unidade | B1: grupo_causa | C1: dias_afastamento
A2: BSB | B2: Osteomuscular | C2: 106
A3: BSB | B3: Saúde mental | C3: 90
A4: BSB | B4: Acidente de trabalho | C4: 41
A5: BSB | B5: Respiratório | C5: 51
A6: BSB | B6: Outros | C6: 49
A7: SP | B7: Osteomuscular | C7: 175
A8: SP | B8: Saúde mental | C8: 171
A9: SP | B9: Acidente de trabalho | C9: 97
A10: SP | B10: Respiratório | C10: 60
A11: SP | B11: Outros | C11: 78
A12: GYN | B12: Osteomuscular | C12: 73
A13: GYN | B13: Saúde mental | C13: 63
... A21: BH | B21: Outros | C21: 50

Sheet fAgentesNocivos
A1: id_unidade | B1: agente | C1: referencia_nr15 | D1: setores_expostos | E1: trabalhadores_expostos | F1: grau_insalubridade | G1: medicoes_acima_limite | H1: situacao_controle
A2: BSB | B2: Ruído contínuo ou intermitente | C2: Anexo 1 | D2: Operações, Manutenção | E2: 36 | F2: Médio (20%) | G2: 0 | H2: =IF(G2=0,"Controlado",IF(G2=1,"Em adequação","Sem controle eficaz")) -> Controlado
A3: BSB | B3: Calor | C3: Anexo 3 | D3: Manutenção, Logística | E3: 14 | F3: Médio (20%) | G3: 0 | H3: =IF(G3=0,"Controlado",IF(G3=1,"Em adequação","Sem controle eficaz")) -> Controlado
A4: BSB | B4: Vibração | C4: Anexo 8 | D4: Logística | E4: 10 | F4: Médio (20%) | G4: 0 | H4: =IF(G4=0,"Controlado",IF(G4=1,"Em adequação","Sem controle eficaz")) -> Controlado
A5: BSB | B5: Hidrocarbonetos e óleos minerais | C5: Anexo 13 | D5: Manutenção | E5: 14 | F5: Máximo (40%) | G5: 0 | H5: =IF(G5=0,"Controlado",IF(G5=1,"Em adequação","Sem controle eficaz")) -> Controlado
A6: BSB | B6: Agentes biológicos | C6: Anexo 14 | D6: Atendimento | E6: 12 | F6: Médio (20%) | G6: 0 | H6: =IF(G6=0,"Controlado",IF(G6=1,"Em adequação","Sem controle eficaz")) -> Controlado
A7: SP | B7: Ruído contínuo ou intermitente | C7: Anexo 1 | D7: Operações, Manutenção | E7: 211 | F7: Médio (20%) | G7: 0 | H7: =IF(G7=0,"Controlado",IF(G7=1,"Em adequação","Sem controle eficaz")) -> Controlado
A8: SP | B8: Calor | C8: Anexo 3 | D8: Manutenção, Logística | E8: 51 | F8: Médio (20%) | G8: 0 | H8: =IF(G8=0,"Controlado",IF(G8=1,"Em adequação","Sem controle eficaz")) -> Controlado
A9: SP | B9: Vibração | C9: Anexo 8 | D9: Logística | E9: 55 | F9: Médio (20%) | G9: 0 | H9: =IF(G9=0,"Controlado",IF(G9=1,"Em adequação","Sem controle eficaz")) -> Controlado
A10: SP | B10: Hidrocarbonetos e óleos minerais | C10: Anexo 13 | D10: Manutenção | E10: 58 | F10: Máximo (40%) | G10: 0 | H10: =IF(G10=0,"Controlado",IF(G10=1,"Em adequação","Sem controle eficaz")) -> Controlado
A11: SP | B11: Agentes biológicos | C11: Anexo 14 | D11: Atendimento | E11: 63 | F11: Médio (20%) | G11: 0 | H11: =IF(G11=0,"Controlado",IF(G11=1,"Em adequação","Sem controle eficaz")) -> Controlado
A12: GYN | B12: Ruído contínuo ou intermitente | C12: Anexo 1 | D12: Operações, Manutenção | E12: 66 | F12: Médio (20%) | G12: 0 | H12: =IF(G12=0,"Controlado",IF(G12=1,"Em adequação","Sem controle eficaz")) -> Controlado
A13: GYN | B13: Calor | C13: Anexo 3 | D13: Manutenção, Logística | E13: 15 | F13: Médio (20%) | G13: 0 | H13: =IF(G13=0,"Controlado",IF(G13=1,"Em adequação","Sem controle eficaz")) -> Controlado
... A21: BH | B21: Agentes biológicos | C21: Anexo 14 | D21: Atendimento | E21: 34 | F21: Médio (20%) | G21: 0 | H21: =IF(G21=0,"Controlado",IF(G21=1,"Em adequação","Sem controle eficaz")) -> Controlado

Sheet fEventosEsocial
A1: id_unidade | B1: evento | C1: descricao | D1: prazo_envio | E1: enviados | F1: pendentes | G1: rejeitados
A2: BSB | B2: S-2210 | C2: Comunicação de Acidente de Trabalho (CAT) | D2: Até o 1º dia útil após o acidente; imediato em caso de óbito | E2: 12 | F2: 0 | G2: 0
A3: BSB | B3: S-2220 | C3: Monitoramento da saúde do trabalhador (ASO) | D3: Até o dia 15 do mês seguinte ao exame | E3: 973 | F3: 4 | G3: 1
A4: BSB | B4: S-2240 | C4: Condições ambientais do trabalho (agentes nocivos) | D4: Até o dia 15 do mês seguinte ao início ou alteração | E4: 285 | F4: 2 | G4: 0
A5: SP | B5: S-2210 | C5: Comunicação de Acidente de Trabalho (CAT) | D5: Até o 1º dia útil após o acidente; imediato em caso de óbito | E5: 19 | F5: 0 | G5: 0
A6: SP | B6: S-2220 | C6: Monitoramento da saúde do trabalhador (ASO) | D6: Até o dia 15 do mês seguinte ao exame | E6: 1401 | F6: 11 | G6: 4
A7: SP | B7: S-2240 | C7: Condições ambientais do trabalho (agentes nocivos) | D7: Até o dia 15 do mês seguinte ao início ou alteração | E7: 397 | F7: 6 | G7: 0
A8: GYN | B8: S-2210 | C8: Comunicação de Acidente de Trabalho (CAT) | D8: Até o 1º dia útil após o acidente; imediato em caso de óbito | E8: 12 | F8: 0 | G8: 0
A9: GYN | B9: S-2220 | C9: Monitoramento da saúde do trabalhador (ASO) | D9: Até o dia 15 do mês seguinte ao exame | E9: 515 | F9: 5 | G9: 2
A10: GYN | B10: S-2240 | C10: Condições ambientais do trabalho (agentes nocivos) | D10: Até o dia 15 do mês seguinte ao início ou alteração | E10: 140 | F10: 3 | G10: 1
A11: BH | B11: S-2210 | C11: Comunicação de Acidente de Trabalho (CAT) | D11: Até o 1º dia útil após o acidente; imediato em caso de óbito | E11: 17 | F11: 1 | G11: 0
A12: BH | B12: S-2220 | C12: Monitoramento da saúde do trabalhador (ASO) | D12: Até o dia 15 do mês seguinte ao exame | E12: 694 | F12: 10 | G12: 3
A13: BH | B13: S-2240 | C13: Condições ambientais do trabalho (agentes nocivos) | D13: Até o dia 15 do mês seguinte ao início ou alteração | E13: 189 | F13: 5 | G13: 2

Sheet dMetas
A1: id_indicador | B1: indicador | C1: meta | D1: sentido | E1: unidade_medida | F1: selos_afetados | G1: bloqueante_para | H1: sugestao_melhoria
A2: trust | B2: Trust Index (% de respostas favoráveis) | C2: 0.7 | D2: Maior ou igual | E2: Percentual | F2: GPTW | G2: GPTW | H2: Divulgar o resultado por área em até 30 dias, construir planos de ação com as próprias equipes e priorizar os temas de menor favorabilidade, como reconhecimento, imparcialidade e comunicação da liderança.
A3: psi | B3: Segurança psicológica (nota da pesquisa) | C3: 7.5 | D3: Maior ou igual | E3: Nota de 0 a 10 | F3: GPTW, ISO 45001, ESG | H3: Incluir os fatores de risco psicossociais no inventário do PGR, capacitar as lideranças em escuta ativa e garantir anonimato e devolutiva no canal de reporte.
A4: nr1 | B4: Conformidade NR-1 / GRO | C4: 0.9 | D4: Maior ou igual | E4: Percentual | F4: ISO 45001, ESG | H4: Tratar os itens não conformes do checklist do GRO por ordem de risco, atualizar o plano de ação do PGR com responsáveis e prazos e registrar as evidências de implementação.
A5: tf | B5: Taxa de frequência de acidentes com afastamento | C5: 3 | D5: Menor ou igual | E5: Número | F5: ISO 45001, ESG | H5: Reforçar a análise de causa raiz dos acidentes, ampliar as inspeções comportamentais nos setores de maior exposição e revisar as permissões para trabalho de risco.
A6: horas | B6: Horas de treinamento em SST por colaborador/ano | C6: 12 | D6: Maior ou igual | E6: Horas por colaborador | F6: ISO 45001, ESG, GPTW | H6: Montar trilha anual obrigatória por função, com integração, NRs aplicáveis e reciclagens em formatos curtos, e acompanhar a presença por unidade.
A7: ncs | B7: Não conformidades abertas na auditoria interna de SST | C7: 3 | D7: Menor ou igual | E7: Quantidade por unidade (no consolidado: 3 × nº de unidades) | F7: ISO 45001 | H7: Fazer mutirão de tratamento das não conformidades com análise de causa, definir responsável e prazo para cada uma e verificar a eficácia antes da auditoria externa.
A8: invest | B8: Investigações de incidentes concluídas no prazo | C8: 0.9 | D8: Maior ou igual | E8: Percentual | F8: ISO 45001 | H8: Padronizar o prazo no POP de investigação de acidentes, automatizar lembretes e envolver a CIPA e os trabalhadores na análise.
A9: abs | B9: Taxa de absenteísmo | C9: 0.03 | D9: Menor ou igual | E9: Percentual | F9: ESG, GPTW | H9: Analisar os afastamentos por setor e por causa com os dados agregados do PCMSO e concentrar as ações de saúde onde a incidência é maior.
A10: part | B10: Participação na pesquisa de clima de segurança | C10: 0.75 | D10: Maior ou igual | E10: Percentual | F10: GPTW | H10: Ampliar a janela de coleta, oferecer acesso pelo celular e por totens às equipes operacionais e reforçar a garantia de confidencialidade.
A11: brig | B11: Brigadistas com treinamento válido | C11: 0.95 | D11: Maior ou igual | E11: Percentual | F11: ISO 45001 | H11: Agendar a reciclagem imediata dos brigadistas vencidos e recrutar voluntários nos turnos com menor cobertura.
A12: turn | B12: Turnover voluntário (12 meses) | C12: 0.12 | D12: Menor ou igual | E12: Percentual | F12: GPTW, ESG | H12: Aplicar entrevistas de desligamento estruturadas e cruzar os motivos de saída com os resultados da pesquisa de clima.
A13: docs | B13: Documentos de SST vigentes | C13: 1 | D13: Maior ou igual | E13: Percentual | F13: ISO 45001, ESG | H13: Priorizar a revisão dos documentos vencidos e manter calendário de revisões com alerta automático 90 dias antes do prazo.

Sheet Conferencia
A1: Conferência: indicadores recalculados a partir das tabelas × valores exibidos no painel (consolidado, todas as unidades)
A2: Coluna C: fórmulas sobre as tabelas desta base. Coluna D (azul): valor exibido no painel HTML, copiado do relatório. Coluna E: diferença.
A4: Indicador | B4: Regra de cálculo | C4: Calculado na base | D4: Valor no painel | E4: Diferença
A5: Colaboradores | B5: Soma de dUnidade[colaboradores] | C5: =SUM(dUnidade!F2:F5) -> 2940 | D5: 2940 | E5: =C5-D5 -> 0
A6: Taxa de frequência (CAF) | B6: Acidentes CAF ÷ horas-homem × 1.000.000 | C6: =SUM(fAcidentesMensal!C:C)/SUM(dUnidade!G2:G5)*1000000 -> 3.0921459 | D6: 3.0921459 | E6: =C6-D6 -> 0
A7: Taxa de gravidade | B7: Dias perdidos ÷ horas-homem × 1.000.000 | C7: =SUM(fIndicadoresGestao!C2:C5)/SUM(dUnidade!G2:G5)*1000000 -> 59.953274 | D7: 59.953274 | E7: =C7-D7 -> 0
A8: Conformidade NR-1 | B8: Média ponderada pelo efetivo | C8: =SUMPRODUCT(fIndicadoresGestao!E2:E5,SUMIF(dUnidade!A2:A5,fIndicadoresGestao!A2:A5,dUnidade!F2:F5))/SUM(dUnidade!F2:F5) -> 0.86828027 | D8: 0.86828427 | E8: =C8-D8 -> -3.9990868e-06
A9: Brigadistas com treinamento válido | B9: Não vencidos ÷ exigidos (limitado a 100%) | C9: =MIN(1,(COUNTA(fBrigadistas!A:A)-1-COUNTIF(fBrigadistas!I:I,"Vencido"))/SUM(fIndicadoresGestao!L2:L5)) -> 0.97560976 | D9: 0.97560976 | E9: =C9-D9 -> 0
A10: Equipamentos vencidos | B10: Contagem de situação = Vencido | C10: =COUNTIF(fEquipamentos!I:I,"Vencido") -> 8 | D10: 8 | E10: =C10-D10 -> 0
A11: Documentos fora da vigência | B11: Contagem de vigência = Vencido | C11: =COUNTIF(fDocumentos!K:K,"Vencido") -> 3 | D11: 3 | E11: =C11-D11 -> 0
A12: Nota de percepção de segurança | B12: Média das dimensões ponderada pelos respondentes | C12: =SUMPRODUCT(fPesquisaDimensao!D2:D29,SUMIF(fIndicadoresGestao!A2:A5,fPesquisaDimensao!A2:A29,fIndicadoresGestao!M2:M5))/(SUM(fIndicadoresGestao!M2:M5)*7) -> 7.0920507 | D12: 7.0917338 | E12: =C12-D12 -> 0.00031691414
A13: Cobertura do SESMT | B13: (Exigido − déficit) ÷ exigido | C13: =(SUM(fSesmt!C:C)-SUM(fSesmt!E:E))/SUM(fSesmt!C:C) -> 0.86956522 | D13: 0.86956522 | E13: =C13-D13 -> 0
A14: ASOs periódicos em dia | B14: 1 − vencidos ÷ total previsto | C14: =1-SUM(fIndicadoresGestao!O2:O5)/SUM(fIndicadoresGestao!N2:N5) -> 0.92857143 | D14: 0.92857143 | E14: =C14-D14 -> 0
A15: PPP disponível nos desligamentos | B15: PPP emitidos ÷ desligamentos | C15: =SUM(fIndicadoresGestao!R2:R5)/SUM(fIndicadoresGestao!Q2:Q5) -> 0.93518519 | D15: 0.93518519 | E15: =C15-D15 -> 0
A17: Resultado da conferência | C17: =IF(SUMPRODUCT(ABS(E5:E15))<0.01,"Base confere com o painel","Verificar diferenças") -> Base confere com o painel
A18: Observação: notas e percentuais das tabelas estão arredondados (2 e 4 casas); diferenças abaixo de 0,01 vêm só desse arredondamento.

Sheet Dicionario
A1: tabela | B1: coluna | C1: tipo | D1: descricao | E1: relacionamento
A2: dUnidade | B2: id_unidade | C2: Texto (chave) | D2: Sigla da unidade
A3: dUnidade | B3: nome_unidade | C3: Texto | D3: Nome completo da unidade
A4: dUnidade | B4: tipo | C4: Texto | D4: Matriz ou Filial
A5: dUnidade | B5: cidade | C5: Texto | D5: Cidade
A6: dUnidade | B6: uf | C6: Texto | D6: Unidade da Federação
A7: dUnidade | B7: colaboradores | C7: Inteiro | D7: Efetivo atual
A8: dUnidade | B8: horas_homem_ano | C8: Inteiro | D8: Horas-homem trabalhadas em 12 meses (colaboradores × 1980 h)
A9: dUnidade | B9: grau_risco | C9: Inteiro | D9: Grau de risco da atividade (NR-4), usado no dimensionamento do SESMT
A10: dSetor | B10: setor | C10: Texto (chave) | D10: Nome do setor
A11: dCalendario | B11: mes | C11: Data (chave) | D11: Primeiro dia do mês
A12: dCalendario | B12: ano | C12: Inteiro | D12: Ano
A13: dCalendario | B13: numero_mes | C13: Inteiro | D13: Número do mês
... A15: dCalendario | B15: semestre | C15: Texto | D15: Semestre do ano
A16: fAcidentesMensal | B16: id_unidade | C16: Texto | D16: Sigla da unidade | E16: dUnidade[id_unidade]
A17: fAcidentesMensal | B17: mes | C17: Data | D17: Mês da ocorrência | E17: dCalendario[mes]
A18: fAcidentesMensal | B18: acidentes_caf | C18: Inteiro | D18: Acidentes com afastamento (CAF)
A19: fAcidentesMensal | B19: acidentes_saf | C19: Inteiro | D19: Acidentes sem afastamento (SAF)
A20: fRiscos | B20: id_unidade | C20: Texto | D20: Sigla da unidade | E20: dUnidade[id_unidade]
A21: fRiscos | B21: setor | C21: Texto | D21: Setor | E21: dSetor[setor]
A22: fRiscos | B22: categoria_risco | C22: Texto | D22: Físico, Químico, Biológico, Ergonômico, Acidentes ou Psicossociais
A23: fRiscos | B23: qtd_perigos | C23: Inteiro | D23: Quantidade de perigos identificados
A24: fBrigadistas | B24: id_brigadista | C24: Texto (chave) | D24: Identificador do brigadista
A25: fBrigadistas | B25: nome | C25: Texto | D25: Nome (fictício)
A26: fBrigadistas | B26: id_unidade | C26: Texto | D26: Sigla da unidade | E26: dUnidade[id_unidade]
A27: fBrigadistas | B27: setor | C27: Texto | D27: Setor de lotação | E27: dSetor[setor]
A28: fBrigadistas | B28: turno | C28: Texto | D28: Turno de trabalho
A29: fBrigadistas | B29: data_ultimo_treinamento | C29: Data | D29: Data do último treinamento de brigada
A30: fBrigadistas | B30: data_validade | C30: Data | D30: Validade do treinamento (reciclagem anual)
A31: fBrigadistas | B31: dias_para_vencimento | C31: Fórmula | D31: data_validade − data de referência (negativo = vencido)
A32: fBrigadistas | B32: situacao | C32: Fórmula | D32: Vencido, Vence em até 30 dias, Vence em até 60 dias ou Válido
A33: fEquipamentos | B33: codigo | C33: Texto (chave) | D33: Código patrimonial do item
A34: fEquipamentos | B34: item | C34: Texto | D34: Descrição do item
A35: fEquipamentos | B35: categoria | C35: Texto | D35: Extintor, Hidrante, EPI, Kit ou Emergência
A36: fEquipamentos | B36: local | C36: Texto | D36: Local de instalação ou guarda
A37: fEquipamentos | B37: id_unidade | C37: Texto | D37: Sigla da unidade | E37: dUnidade[id_unidade]
A38: fEquipamentos | B38: quantidade | C38: Inteiro | D38: Quantidade (lotes de EPI em unidades)
A39: fEquipamentos | B39: data_validade | C39: Data | D39: Validade ou próxima manutenção/recarga
A40: fEquipamentos | B40: dias_para_vencimento | C40: Fórmula | D40: data_validade − data de referência
A41: fEquipamentos | B41: situacao | C41: Fórmula | D41: Vencido, Até 30 dias, 31 a 90 dias ou Em dia
...
